[2025-01-08T07:30:57.010+0000] {local_task_job_runner.py:120} INFO - ::group::Pre task execution logs
[2025-01-08T07:30:57.196+0000] {taskinstance.py:2076} INFO - Dependencies all met for dep_context=non-requeueable deps ti=<TaskInstance: e_commerce_dw_etl.transform.transform_dim_dates manual__2025-01-08T07:29:39.833688+00:00 [queued]>
[2025-01-08T07:30:57.253+0000] {taskinstance.py:2076} INFO - Dependencies all met for dep_context=requeueable deps ti=<TaskInstance: e_commerce_dw_etl.transform.transform_dim_dates manual__2025-01-08T07:29:39.833688+00:00 [queued]>
[2025-01-08T07:30:57.263+0000] {taskinstance.py:2306} INFO - Starting attempt 1 of 1
[2025-01-08T07:30:57.426+0000] {taskinstance.py:2330} INFO - Executing <Task(PythonOperator): transform.transform_dim_dates> on 2025-01-08 07:29:39.833688+00:00
[2025-01-08T07:30:57.445+0000] {standard_task_runner.py:63} INFO - Started process 2554 to run task
[2025-01-08T07:30:57.453+0000] {standard_task_runner.py:90} INFO - Running: ['***', 'tasks', 'run', 'e_commerce_dw_etl', 'transform.transform_dim_dates', 'manual__2025-01-08T07:29:39.833688+00:00', '--job-id', '902', '--raw', '--subdir', 'DAGS_FOLDER/e_commerce_dw_dag.py', '--cfg-path', '/tmp/tmpuxvmbkdl']
[2025-01-08T07:30:57.468+0000] {standard_task_runner.py:91} INFO - Job 902: Subtask transform.transform_dim_dates
[2025-01-08T07:30:57.790+0000] {task_command.py:426} INFO - Running <TaskInstance: e_commerce_dw_etl.transform.transform_dim_dates manual__2025-01-08T07:29:39.833688+00:00 [running]> on host 4ff5b0867c78
[2025-01-08T07:30:58.254+0000] {taskinstance.py:2648} INFO - Exporting env vars: AIRFLOW_CTX_DAG_OWNER='***' AIRFLOW_CTX_DAG_ID='e_commerce_dw_etl' AIRFLOW_CTX_TASK_ID='transform.transform_dim_dates' AIRFLOW_CTX_EXECUTION_DATE='2025-01-08T07:29:39.833688+00:00' AIRFLOW_CTX_TRY_NUMBER='1' AIRFLOW_CTX_DAG_RUN_ID='manual__2025-01-08T07:29:39.833688+00:00'
[2025-01-08T07:30:58.259+0000] {taskinstance.py:430} INFO - ::endgroup::
[2025-01-08T07:30:58.612+0000] {base.py:84} INFO - Using connection ID 'postgres' for task execution.
[2025-01-08T07:30:59.342+0000] {taskinstance.py:441} INFO - ::group::Post task execution logs
[2025-01-08T07:30:59.351+0000] {taskinstance.py:2905} ERROR - Task failed with exception
Traceback (most recent call last):
  File "/home/airflow/.local/lib/python3.10/site-packages/sqlalchemy/engine/base.py", line 1910, in _execute_context
    self.dialect.do_execute(
  File "/home/airflow/.local/lib/python3.10/site-packages/sqlalchemy/engine/default.py", line 736, in do_execute
    cursor.execute(statement, parameters)
psycopg2.errors.InvalidSchemaName: schema "warehouse" does not exist
LINE 2: CREATE TABLE warehouse.dim_dates (
                     ^


The above exception was the direct cause of the following exception:

Traceback (most recent call last):
  File "/home/airflow/.local/lib/python3.10/site-packages/airflow/models/taskinstance.py", line 465, in _execute_task
    result = _execute_callable(context=context, **execute_callable_kwargs)
  File "/home/airflow/.local/lib/python3.10/site-packages/airflow/models/taskinstance.py", line 432, in _execute_callable
    return execute_callable(context=context, **execute_callable_kwargs)
  File "/home/airflow/.local/lib/python3.10/site-packages/airflow/models/baseoperator.py", line 401, in wrapper
    return func(self, *args, **kwargs)
  File "/home/airflow/.local/lib/python3.10/site-packages/airflow/operators/python.py", line 235, in execute
    return_value = self.execute_callable()
  File "/home/airflow/.local/lib/python3.10/site-packages/airflow/operators/python.py", line 252, in execute_callable
    return self.python_callable(*self.op_args, **self.op_kwargs)
  File "/opt/airflow/dags/transform_dim_dates.py", line 26, in transform_dim_dates
    warehouse_operator.save_data_to_postgres(
  File "/opt/airflow/plugins/postgresql_operator.py", line 19, in save_data_to_postgres
    df.to_sql(table_name, engine, schema=schema, if_exists=if_exists, index=False)
  File "/home/airflow/.local/lib/python3.10/site-packages/pandas/core/generic.py", line 2987, in to_sql
    return sql.to_sql(
  File "/home/airflow/.local/lib/python3.10/site-packages/pandas/io/sql.py", line 695, in to_sql
    return pandas_sql.to_sql(
  File "/home/airflow/.local/lib/python3.10/site-packages/pandas/io/sql.py", line 1728, in to_sql
    table = self.prep_table(
  File "/home/airflow/.local/lib/python3.10/site-packages/pandas/io/sql.py", line 1631, in prep_table
    table.create()
  File "/home/airflow/.local/lib/python3.10/site-packages/pandas/io/sql.py", line 838, in create
    self._execute_create()
  File "/home/airflow/.local/lib/python3.10/site-packages/pandas/io/sql.py", line 824, in _execute_create
    self.table.create(bind=self.pd_sql.connectable)
  File "/home/airflow/.local/lib/python3.10/site-packages/sqlalchemy/sql/schema.py", line 962, in create
    bind._run_ddl_visitor(ddl.SchemaGenerator, self, checkfirst=checkfirst)
  File "/home/airflow/.local/lib/python3.10/site-packages/sqlalchemy/engine/base.py", line 3238, in _run_ddl_visitor
    conn._run_ddl_visitor(visitorcallable, element, **kwargs)
  File "/home/airflow/.local/lib/python3.10/site-packages/sqlalchemy/engine/base.py", line 2221, in _run_ddl_visitor
    visitorcallable(self.dialect, self, **kwargs).traverse_single(element)
  File "/home/airflow/.local/lib/python3.10/site-packages/sqlalchemy/sql/visitors.py", line 524, in traverse_single
    return meth(obj, **kw)
  File "/home/airflow/.local/lib/python3.10/site-packages/sqlalchemy/sql/ddl.py", line 899, in visit_table
    self.connection.execute(
  File "/home/airflow/.local/lib/python3.10/site-packages/sqlalchemy/engine/base.py", line 1385, in execute
    return meth(self, multiparams, params, _EMPTY_EXECUTION_OPTS)
  File "/home/airflow/.local/lib/python3.10/site-packages/sqlalchemy/sql/ddl.py", line 80, in _execute_on_connection
    return connection._execute_ddl(
  File "/home/airflow/.local/lib/python3.10/site-packages/sqlalchemy/engine/base.py", line 1477, in _execute_ddl
    ret = self._execute_context(
  File "/home/airflow/.local/lib/python3.10/site-packages/sqlalchemy/engine/base.py", line 1953, in _execute_context
    self._handle_dbapi_exception(
  File "/home/airflow/.local/lib/python3.10/site-packages/sqlalchemy/engine/base.py", line 2134, in _handle_dbapi_exception
    util.raise_(
  File "/home/airflow/.local/lib/python3.10/site-packages/sqlalchemy/util/compat.py", line 211, in raise_
    raise exception
  File "/home/airflow/.local/lib/python3.10/site-packages/sqlalchemy/engine/base.py", line 1910, in _execute_context
    self.dialect.do_execute(
  File "/home/airflow/.local/lib/python3.10/site-packages/sqlalchemy/engine/default.py", line 736, in do_execute
    cursor.execute(statement, parameters)
sqlalchemy.exc.ProgrammingError: (psycopg2.errors.InvalidSchemaName) schema "warehouse" does not exist
LINE 2: CREATE TABLE warehouse.dim_dates (
                     ^

[SQL: 
CREATE TABLE warehouse.dim_dates (
	date_key TIMESTAMP WITHOUT TIME ZONE, 
	day BIGINT, 
	month BIGINT, 
	year BIGINT, 
	quarter BIGINT, 
	day_of_week BIGINT, 
	day_name TEXT, 
	month_name TEXT, 
	is_weekend BOOLEAN
)

]
(Background on this error at: https://sqlalche.me/e/14/f405)
[2025-01-08T07:30:59.440+0000] {taskinstance.py:1206} INFO - Marking task as FAILED. dag_id=e_commerce_dw_etl, task_id=transform.transform_dim_dates, run_id=manual__2025-01-08T07:29:39.833688+00:00, execution_date=20250108T072939, start_date=20250108T073057, end_date=20250108T073059
[2025-01-08T07:30:59.498+0000] {standard_task_runner.py:110} ERROR - Failed to execute job 902 for task transform.transform_dim_dates ((psycopg2.errors.InvalidSchemaName) schema "warehouse" does not exist
LINE 2: CREATE TABLE warehouse.dim_dates (
                     ^

[SQL: 
CREATE TABLE warehouse.dim_dates (
	date_key TIMESTAMP WITHOUT TIME ZONE, 
	day BIGINT, 
	month BIGINT, 
	year BIGINT, 
	quarter BIGINT, 
	day_of_week BIGINT, 
	day_name TEXT, 
	month_name TEXT, 
	is_weekend BOOLEAN
)

]
(Background on this error at: https://sqlalche.me/e/14/f405); 2554)
[2025-01-08T07:30:59.524+0000] {local_task_job_runner.py:240} INFO - Task exited with return code 1
[2025-01-08T07:30:59.562+0000] {local_task_job_runner.py:222} INFO - ::endgroup::
