[2025-01-10T10:26:23.087+0000] {local_task_job_runner.py:120} INFO - ::group::Pre task execution logs
[2025-01-10T10:26:23.124+0000] {taskinstance.py:2076} INFO - Dependencies all met for dep_context=non-requeueable deps ti=<TaskInstance: e_commerce_dw_etl.load.transform_fact_orders scheduled__2025-01-09T00:00:00+00:00 [queued]>
[2025-01-10T10:26:23.134+0000] {taskinstance.py:2076} INFO - Dependencies all met for dep_context=requeueable deps ti=<TaskInstance: e_commerce_dw_etl.load.transform_fact_orders scheduled__2025-01-09T00:00:00+00:00 [queued]>
[2025-01-10T10:26:23.135+0000] {taskinstance.py:2306} INFO - Starting attempt 1 of 1
[2025-01-10T10:26:23.152+0000] {taskinstance.py:2330} INFO - Executing <Task(PythonOperator): load.transform_fact_orders> on 2025-01-09 00:00:00+00:00
[2025-01-10T10:26:23.157+0000] {standard_task_runner.py:63} INFO - Started process 311 to run task
[2025-01-10T10:26:23.160+0000] {standard_task_runner.py:90} INFO - Running: ['***', 'tasks', 'run', 'e_commerce_dw_etl', 'load.transform_fact_orders', 'scheduled__2025-01-09T00:00:00+00:00', '--job-id', '941', '--raw', '--subdir', 'DAGS_FOLDER/e_commerce_dw_dag.py', '--cfg-path', '/tmp/tmpfp3xt4t5']
[2025-01-10T10:26:23.162+0000] {standard_task_runner.py:91} INFO - Job 941: Subtask load.transform_fact_orders
[2025-01-10T10:26:23.213+0000] {task_command.py:426} INFO - Running <TaskInstance: e_commerce_dw_etl.load.transform_fact_orders scheduled__2025-01-09T00:00:00+00:00 [running]> on host 616c357ff125
[2025-01-10T10:26:23.433+0000] {taskinstance.py:2648} INFO - Exporting env vars: AIRFLOW_CTX_DAG_OWNER='***' AIRFLOW_CTX_DAG_ID='e_commerce_dw_etl' AIRFLOW_CTX_TASK_ID='load.transform_fact_orders' AIRFLOW_CTX_EXECUTION_DATE='2025-01-09T00:00:00+00:00' AIRFLOW_CTX_TRY_NUMBER='1' AIRFLOW_CTX_DAG_RUN_ID='scheduled__2025-01-09T00:00:00+00:00'
[2025-01-10T10:26:23.433+0000] {taskinstance.py:430} INFO - ::endgroup::
[2025-01-10T10:26:23.452+0000] {base.py:84} INFO - Using connection ID 'postgres' for task execution.
[2025-01-10T10:26:23.466+0000] {logging_mixin.py:188} WARNING - /home/***/.local/lib/python3.10/site-packages/***/providers/common/sql/hooks/sql.py:263 UserWarning: pandas only supports SQLAlchemy connectable (engine/connection) or database string URI or sqlite3 DBAPI2 connection. Other DBAPI2 objects are not tested. Please consider using SQLAlchemy.
[2025-01-10T10:26:24.411+0000] {base.py:84} INFO - Using connection ID 'postgres' for task execution.
[2025-01-10T10:26:24.421+0000] {logging_mixin.py:188} WARNING - /home/***/.local/lib/python3.10/site-packages/***/providers/common/sql/hooks/sql.py:263 UserWarning: pandas only supports SQLAlchemy connectable (engine/connection) or database string URI or sqlite3 DBAPI2 connection. Other DBAPI2 objects are not tested. Please consider using SQLAlchemy.
[2025-01-10T10:26:25.327+0000] {base.py:84} INFO - Using connection ID 'postgres' for task execution.
[2025-01-10T10:26:25.336+0000] {logging_mixin.py:188} WARNING - /home/***/.local/lib/python3.10/site-packages/***/providers/common/sql/hooks/sql.py:263 UserWarning: pandas only supports SQLAlchemy connectable (engine/connection) or database string URI or sqlite3 DBAPI2 connection. Other DBAPI2 objects are not tested. Please consider using SQLAlchemy.
[2025-01-10T10:26:25.782+0000] {base.py:84} INFO - Using connection ID 'postgres' for task execution.
[2025-01-10T10:26:25.790+0000] {logging_mixin.py:188} WARNING - /home/***/.local/lib/python3.10/site-packages/***/providers/common/sql/hooks/sql.py:263 UserWarning: pandas only supports SQLAlchemy connectable (engine/connection) or database string URI or sqlite3 DBAPI2 connection. Other DBAPI2 objects are not tested. Please consider using SQLAlchemy.
[2025-01-10T10:26:26.424+0000] {logging_mixin.py:188} INFO - Các cột trong DataFrame sau khi merge:
[2025-01-10T10:26:26.426+0000] {logging_mixin.py:188} INFO - Index(['order_id', 'customer_id', 'order_status', 'order_purchase_timestamp',
       'order_approved_at', 'order_delivered_carrier_date',
       'order_delivered_customer_date', 'order_estimated_delivery_date',
       'order_item_id', 'product_id', 'seller_id', 'shipping_limit_date',
       'price', 'freight_value', 'payment_sequential', 'payment_type',
       'payment_installments', 'payment_value', 'customer_zip_code_prefix'],
      dtype='object')
[2025-01-10T10:26:26.586+0000] {taskinstance.py:441} INFO - ::group::Post task execution logs
[2025-01-10T10:26:26.588+0000] {taskinstance.py:2905} ERROR - Task failed with exception
Traceback (most recent call last):
  File "/home/airflow/.local/lib/python3.10/site-packages/pandas/core/indexes/base.py", line 3802, in get_loc
    return self._engine.get_loc(casted_key)
  File "pandas/_libs/index.pyx", line 138, in pandas._libs.index.IndexEngine.get_loc
  File "pandas/_libs/index.pyx", line 165, in pandas._libs.index.IndexEngine.get_loc
  File "pandas/_libs/hashtable_class_helper.pxi", line 5745, in pandas._libs.hashtable.PyObjectHashTable.get_item
  File "pandas/_libs/hashtable_class_helper.pxi", line 5753, in pandas._libs.hashtable.PyObjectHashTable.get_item
KeyError: '`order_purchase_timestam`p'

The above exception was the direct cause of the following exception:

Traceback (most recent call last):
  File "/home/airflow/.local/lib/python3.10/site-packages/airflow/models/taskinstance.py", line 465, in _execute_task
    result = _execute_callable(context=context, **execute_callable_kwargs)
  File "/home/airflow/.local/lib/python3.10/site-packages/airflow/models/taskinstance.py", line 432, in _execute_callable
    return execute_callable(context=context, **execute_callable_kwargs)
  File "/home/airflow/.local/lib/python3.10/site-packages/airflow/models/baseoperator.py", line 401, in wrapper
    return func(self, *args, **kwargs)
  File "/home/airflow/.local/lib/python3.10/site-packages/airflow/operators/python.py", line 235, in execute
    return_value = self.execute_callable()
  File "/home/airflow/.local/lib/python3.10/site-packages/airflow/operators/python.py", line 252, in execute_callable
    return self.python_callable(*self.op_args, **self.op_kwargs)
  File "/opt/airflow/dags/transform_fact_orders.py", line 34, in transform_fact_orders
    df['estimated_delivery_time'] = (df['order_estimated_delivery_date'] - df['`order_purchase_timestam`p']).dt.total_seconds() / 86400
  File "/home/airflow/.local/lib/python3.10/site-packages/pandas/core/frame.py", line 3807, in __getitem__
    indexer = self.columns.get_loc(key)
  File "/home/airflow/.local/lib/python3.10/site-packages/pandas/core/indexes/base.py", line 3804, in get_loc
    raise KeyError(key) from err
KeyError: '`order_purchase_timestam`p'
[2025-01-10T10:26:26.612+0000] {taskinstance.py:1206} INFO - Marking task as FAILED. dag_id=e_commerce_dw_etl, task_id=load.transform_fact_orders, run_id=scheduled__2025-01-09T00:00:00+00:00, execution_date=20250109T000000, start_date=20250110T102623, end_date=20250110T102626
[2025-01-10T10:26:26.629+0000] {standard_task_runner.py:110} ERROR - Failed to execute job 941 for task load.transform_fact_orders ('`order_purchase_timestam`p'; 311)
[2025-01-10T10:26:26.679+0000] {local_task_job_runner.py:240} INFO - Task exited with return code 1
[2025-01-10T10:26:26.696+0000] {taskinstance.py:3503} INFO - 0 downstream tasks scheduled from follow-on schedule check
[2025-01-10T10:26:26.700+0000] {local_task_job_runner.py:222} INFO - ::endgroup::
